
[E 180730 18:59:21 torndb:103] Cannot connect to MySQL on 127.0.0.1
    Traceback (most recent call last):
      File "/home/liu/.local/lib/python2.7/site-packages/torndb.py", line 100, in __init__
        self.reconnect()
      File "/home/liu/.local/lib/python2.7/site-packages/torndb.py", line 117, in reconnect
        self._db = MySQLdb.connect(**self._db_args)
      File "/usr/lib/python2.7/dist-packages/MySQLdb/__init__.py", line 86, in Connect
        return Connection(*args, **kwargs)
      File "/usr/lib/python2.7/dist-packages/MySQLdb/connections.py", line 204, in __init__
        super(Connection, self).__init__(*args, **kwargs2)
    OperationalError: (1049, "Unknown database 'ihome'")
[W 180730 19:00:00 Passport:9] warning msg
[E 180730 19:00:00 Passport:10] error msg
[E 180730 19:00:52 web:1670] Uncaught exception GET /api/imagecode?codeid=123&pcodeid= (127.0.0.1)
    HTTPServerRequest(protocol='http', host='127.0.0.1:8000', method='GET', uri='/api/imagecode?codeid=123&pcodeid=', version='HTTP/1.1', remote_ip='127.0.0.1')
    Traceback (most recent call last):
      File "/home/liu/.local/lib/python2.7/site-packages/tornado/web.py", line 1590, in _execute
        result = method(*self.path_args, **self.path_kwargs)
      File "/home/liu/PycharmProjects/python2.7/Tornado_Project/handlers/VerifvCode.py", line 22, in get
        name,text,image = captcha.generate_captcha()
    AttributeError: 'module' object has no attribute 'generate_captcha'
[E 180730 19:00:52 web:2162] 500 GET /api/imagecode?codeid=123&pcodeid= (127.0.0.1) 17.72ms
[E 180730 19:07:19 web:1670] Uncaught exception GET /api/imagecode?codeid=123&pcodeid= (127.0.0.1)
    HTTPServerRequest(protocol='http', host='127.0.0.1:8000', method='GET', uri='/api/imagecode?codeid=123&pcodeid=', version='HTTP/1.1', remote_ip='127.0.0.1')
    Traceback (most recent call last):
      File "/home/liu/.local/lib/python2.7/site-packages/tornado/web.py", line 1590, in _execute
        result = method(*self.path_args, **self.path_kwargs)
      File "/home/liu/PycharmProjects/python2.7/Tornado_Project/handlers/VerifvCode.py", line 22, in get
        name,text,image = captcha.generate_captcha()
    AttributeError: 'module' object has no attribute 'generate_captcha'
[E 180730 19:07:19 web:2162] 500 GET /api/imagecode?codeid=123&pcodeid= (127.0.0.1) 0.83ms
[E 180730 19:12:15 torndb:103] Cannot connect to MySQL on 127.0.0.1
    Traceback (most recent call last):
      File "/home/liu/.local/lib/python2.7/site-packages/torndb.py", line 100, in __init__
        self.reconnect()
      File "/home/liu/.local/lib/python2.7/site-packages/torndb.py", line 117, in reconnect
        self._db = MySQLdb.connect(**self._db_args)
      File "/usr/lib/python2.7/dist-packages/MySQLdb/__init__.py", line 86, in Connect
        return Connection(*args, **kwargs)
      File "/usr/lib/python2.7/dist-packages/MySQLdb/connections.py", line 204, in __init__
        super(Connection, self).__init__(*args, **kwargs2)
    OperationalError: (1049, "Unknown database 'ihome'")
[W 180730 19:12:16 web:2162] 404 GET /favicon.ico (127.0.0.1) 2.60ms
[E 180730 20:11:19 torndb:103] Cannot connect to MySQL on 127.0.0.1
    Traceback (most recent call last):
      File "/home/liu/.local/lib/python2.7/site-packages/torndb.py", line 100, in __init__
        self.reconnect()
      File "/home/liu/.local/lib/python2.7/site-packages/torndb.py", line 117, in reconnect
        self._db = MySQLdb.connect(**self._db_args)
      File "/usr/lib/python2.7/dist-packages/MySQLdb/__init__.py", line 86, in Connect
        return Connection(*args, **kwargs)
      File "/usr/lib/python2.7/dist-packages/MySQLdb/connections.py", line 204, in __init__
        super(Connection, self).__init__(*args, **kwargs2)
    OperationalError: (1049, "Unknown database 'ihome'")
[E 180730 20:13:32 torndb:103] Cannot connect to MySQL on 127.0.0.1
    Traceback (most recent call last):
      File "/home/liu/.local/lib/python2.7/site-packages/torndb.py", line 100, in __init__
        self.reconnect()
      File "/home/liu/.local/lib/python2.7/site-packages/torndb.py", line 117, in reconnect
        self._db = MySQLdb.connect(**self._db_args)
      File "/usr/lib/python2.7/dist-packages/MySQLdb/__init__.py", line 86, in Connect
        return Connection(*args, **kwargs)
      File "/usr/lib/python2.7/dist-packages/MySQLdb/connections.py", line 204, in __init__
        super(Connection, self).__init__(*args, **kwargs2)
    OperationalError: (1049, "Unknown database 'ihome'")
